Workbook

Sheet Orientações e escalas
A2: Os dados devem ser preenchidos nas abas (SEM 1, SEM 2, SEM 3 e SEM 4). Os resultados serão obtidos a partir desse prenchimento e visualizados em tabelas e gráficos. As escalas estão disponíveis abaixo:

Sheet SEM 1
A1: SEMANA 1 | L1: Son | M1: Estr | N1: Fad | O1: Dor | Q1: Média | T1: Teste de potência
A2: SEGUNDA-FEIRA | C2: DATA | E2: 45600 | L2: 5 | M2: 5 | N2: 5 | O2: 5 | Q2: =IFERROR(AVERAGE(L2:O2),"") | S2: =Q2
A3: Exercícios | B3: série 1 | G3: série 2 | L3: série 3 | Q3: série 4 | V3: série 5 | AA3: VEL (2x1) | AB3: VEL (3x1) | AC3: VEL (4x1) | AD3: VEL (5x1) | AG3: VTT-SESSÃO | AJ3: CARGA DE TREINO (U.A)
B4: nº reps | C4: peso(kg) | D4: veloc(s) | E4: VTT (sér) | G4: nº reps | H4: peso(kg) | I4: veloc(s) | J4: VTT (sér) | L4: nº reps | M4: peso(kg) | N4: veloc(s) | O4: VTT (sér) | Q4: nº reps | R4: peso(kg) | S4: veloc(s) | T4: VTT (sér) | V4: nº reps | W4: peso(kg) | X4: veloc(s) | Y4: VTT (sér) | AG4: =SUM(E18+J18+O18+T18+Y18) | AJ4: =AE5*AG7
A5: Leg Press 45 | B5: 12 | C5: 100 | D5: 2 | G5: 12 | H5: 100 | I5: 2 | J5: =G5*H5 | L5: 12 | M5: 100 | N5: 2 | O5: =L5*M5 | Q5: 12 | R5: 100 | S5: 2 | T5: =Q5*R5 | Y5: =V5*W5 | AA5: =IFERROR(((I5-D5)/D5)*100,"") | AB5: =IFERROR(((N5-D5)/D5)*100,"") | AC5: =IFERROR(((S5-D5)/D5)*100,"") | AD5: =IFERROR(((X5-D5)/D5)*100,"") | AE5: 7
E6: =B6*C6 | J6: =G6*H6 | O6: =L6*M6 | T6: =Q6*R6 | Y6: =V6*W6 | AA6: =IFERROR(((I6-D6)/D6)*100,"") | AB6: =IFERROR(((N6-D6)/D6)*100,"") | AC6: =IFERROR(((S6-D6)/D6)*100,"") | AD6: =IFERROR(((X6-D6)/D6)*100,"") | AG6: Tempo total sessão (min)
E7: =B7*C7 | J7: =G7*H7 | O7: =L7*M7 | T7: =Q7*R7 | Y7: =V7*W7 | AA7: =IFERROR(((I7-D7)/D7)*100,"") | AB7: =IFERROR(((N7-D7)/D7)*100,"") | AC7: =IFERROR(((S7-D7)/D7)*100,"") | AD7: =IFERROR(((X7-D7)/D7)*100,"") | AG7: 50
E8: =B8*C8 | J8: =G8*H8 | O8: =L8*M8 | T8: =Q8*R8 | Y8: =V8*W8 | AA8: =IFERROR(((I8-D8)/D8)*100,"") | AB8: =IFERROR(((N8-D8)/D8)*100,"") | AC8: =IFERROR(((S8-D8)/D8)*100,"") | AD8: =IFERROR(((X8-D8)/D8)*100,"")
E9: =B9*C9 | J9: =G9*H9 | O9: =L9*M9 | T9: =Q9*R9 | Y9: =V9*W9 | AA9: =IFERROR(((I9-D9)/D9)*100,"") | AB9: =IFERROR(((N9-D9)/D9)*100,"") | AC9: =IFERROR(((S9-D9)/D9)*100,"") | AD9: =IFERROR(((X9-D9)/D9)*100,"")
E10: =B10*C10 | J10: =G10*H10 | O10: =L10*M10 | T10: =Q10*R10 | Y10: =V10*W10 | AA10: =IFERROR(((I10-D10)/D10)*100,"") | AB10: =IFERROR(((N10-D10)/D10)*100,"") | AC10: =IFERROR(((S10-D10)/D10)*100,"") | AD10: =IFERROR(((X10-D10)/D10)*100,"")
E11: =B11*C11 | J11: =G11*H11 | O11: =L11*M11 | T11: =Q11*R11 | Y11: =V11*W11 | AA11: =IFERROR(((I11-D11)/D11)*100,"") | AB11: =IFERROR(((N11-D11)/D11)*100,"") | AC11: =IFERROR(((S11-D11)/D11)*100,"") | AD11: =IFERROR(((X11-D11)/D11)*100,"")
E12: =B12*C12 | J12: =G12*H12 | O12: =L12*M12 | T12: =Q12*R12 | Y12: =V12*W12 | AA12: =IFERROR(((I12-D12)/D12)*100,"") | AB12: =IFERROR(((N12-D12)/D12)*100,"") | AC12: =IFERROR(((S12-D12)/D12)*100,"") | AD12: =IFERROR(((X12-D12)/D12)*100,"")
E13: =B13*C13 | J13: =G13*H13 | O13: =L13*M13 | T13: =Q13*R13 | Y13: =V13*W13 | AA13: =IFERROR(((I13-D13)/D13)*100,"") | AB13: =IFERROR(((N13-D13)/D13)*100,"") | AC13: =IFERROR(((S13-D13)/D13)*100,"") | AD13: =IFERROR(((X13-D13)/D13)*100,"")
E14: =B14*C14 | J14: =G14*H14 | O14: =L14*M14 | T14: =Q14*R14 | Y14: =V14*W14 | AA14: =IFERROR(((I14-D14)/D14)*100,"") | AB14: =IFERROR(((N14-D14)/D14)*100,"") | AC14: =IFERROR(((S14-D14)/D14)*100,"") | AD14: =IFERROR(((X14-D14)/D14)*100,"")
E15: =B15*C15 | J15: =G15*H15 | O15: =L15*M15 | T15: =Q15*R15 | Y15: =V15*W15 | AA15: =IFERROR(((I15-D15)/D15)*100,"") | AB15: =IFERROR(((N15-D15)/D15)*100,"") | AC15: =IFERROR(((S15-D15)/D15)*100,"") | AD15: =IFERROR(((X15-D15)/D15)*100,"")
E16: =B16*C16 | J16: =G16*H16 | O16: =L16*M16 | T16: =Q16*R16 | Y16: =V16*W16 | AA16: =IFERROR(((I16-D16)/D16)*100,"") | AB16: =IFERROR(((N16-D16)/D16)*100,"") | AC16: =IFERROR(((S16-D16)/D16)*100,"") | AD16: =IFERROR(((X16-D16)/D16)*100,"") | AN16: =AH16*AH15 | AO16: =AJ16*AJ15 | AP16: =AK16*AK15 | AQ16: =AL16*AL15
E17: PR | J17: PR | O17: PR | T17: PR | AC17: PR-M | AD17: =IFERROR(AVERAGE(G17,L17,Q17,V17),"")
E18: =SUM(E5:E16) | J18: =SUM(J5:J16) | O18: =SUM(O5:O16) | T18: =SUM(T5:T16) | Y18: =SUM(Y5:Y16)
L19: Son | M19: Estr | N19: Fad | O19: Dor | Q19: Média | T19: Teste de potência
A20: TERÇA-FEIRA | C20: DATA | Q20: =IFERROR(AVERAGE(L20:O20),"") | S20: =Q20
A21: Exercícios | B21: série 1 | G21: série 2 | L21: série 3 | Q21: série 4 | V21: série 5 | AA21: VEL (2x1) | AB21: VEL (3x1) | AC21: VEL (4x1) | AD21: VEL (5x1) | AG21: VTT-SESSÃO | AJ21: CARGA DE TREINO (U.A)
B22: nº reps | C22: peso(kg) | D22: veloc(s) | E22: VTT (sér) | G22: nº reps | H22: peso(kg) | I22: veloc(s) | J22: VTT (sér) | L22: nº reps | M22: peso(kg) | N22: veloc(s) | O22: VTT (sér) | Q22: nº reps | R22: peso(kg) | S22: veloc(s) | T22: VTT (sér) | V22: nº reps | W22: peso(kg) | X22: veloc(s) | Y22: VTT (sér) | AG22: =SUM(E36+J36+O36+T36+Y36) | AJ22: =AE23*AG25
A23: Mobilidade | E23: =B23*C23 | J23: =G23*H23 | O23: =L23*M23 | T23: =Q23*R23 | Y23: =V23*W23 | AA23: =IFERROR(((I23-D23)/D23)*100,"") | AB23: =IFERROR(((N23-D23)/D23)*100,"") | AC23: =IFERROR(((S23-D23)/D23)*100,"") | AD23: =IFERROR(((X23-D23)/D23)*100,"")
E24: =B24*C24 | J24: =G24*H24 | O24: =L24*M24 | T24: =Q24*R24 | Y24: =V24*W24 | AA24: =IFERROR(((I24-D24)/D24)*100,"") | AB24: =IFERROR(((N24-D24)/D24)*100,"") | AC24: =IFERROR(((S24-D24)/D24)*100,"") | AD24: =IFERROR(((X24-D24)/D24)*100,"") | AG24: Tempo total sessão (min)
E25: =B25*C25 | J25: =G25*H25 | O25: =L25*M25 | T25: =Q25*R25 | Y25: =V25*W25 | AA25: =IFERROR(((I25-D25)/D25)*100,"") | AB25: =IFERROR(((N25-D25)/D25)*100,"") | AC25: =IFERROR(((S25-D25)/D25)*100,"") | AD25: =IFERROR(((X25-D25)/D25)*100,"")
E26: =B26*C26 | J26: =G26*H26 | O26: =L26*M26 | T26: =Q26*R26 | Y26: =V26*W26 | AA26: =IFERROR(((I26-D26)/D26)*100,"") | AB26: =IFERROR(((N26-D26)/D26)*100,"") | AC26: =IFERROR(((S26-D26)/D26)*100,"") | AD26: =IFERROR(((X26-D26)/D26)*100,"")
E27: =B27*C27 | J27: =G27*H27 | O27: =L27*M27 | T27: =Q27*R27 | Y27: =V27*W27 | AA27: =IFERROR(((I27-D27)/D27)*100,"") | AB27: =IFERROR(((N27-D27)/D27)*100,"") | AC27: =IFERROR(((S27-D27)/D27)*100,"") | AD27: =IFERROR(((X27-D27)/D27)*100,"")
E28: =B28*C28 | J28: =G28*H28 | O28: =L28*M28 | T28: =Q28*R28 | Y28: =V28*W28 | AA28: =IFERROR(((I28-D28)/D28)*100,"") | AB28: =IFERROR(((N28-D28)/D28)*100,"") | AC28: =IFERROR(((S28-D28)/D28)*100,"") | AD28: =IFERROR(((X28-D28)/D28)*100,"")
E29: =B29*C29 | J29: =G29*H29 | O29: =L29*M29 | T29: =Q29*R29 | Y29: =V29*W29 | AA29: =IFERROR(((I29-D29)/D29)*100,"") | AB29: =IFERROR(((N29-D29)/D29)*100,"") | AC29: =IFERROR(((S29-D29)/D29)*100,"") | AD29: =IFERROR(((X29-D29)/D29)*100,"")
E30: =B30*C30 | J30: =G30*H30 | O30: =L30*M30 | T30: =Q30*R30 | Y30: =V30*W30 | AA30: =IFERROR(((I30-D30)/D30)*100,"") | AB30: =IFERROR(((N30-D30)/D30)*100,"") | AC30: =IFERROR(((S30-D30)/D30)*100,"") | AD30: =IFERROR(((X30-D30)/D30)*100,"")
E31: =B31*C31 | J31: =G31*H31 | O31: =L31*M31 | T31: =Q31*R31 | Y31: =V31*W31 | AA31: =IFERROR(((I31-D31)/D31)*100,"") | AB31: =IFERROR(((N31-D31)/D31)*100,"") | AC31: =IFERROR(((S31-D31)/D31)*100,"") | AD31: =IFERROR(((X31-D31)/D31)*100,"")
E32: =B32*C32 | J32: =G32*H32 | O32: =L32*M32 | T32: =Q32*R32 | Y32: =V32*W32 | AA32: =IFERROR(((I32-D32)/D32)*100,"") | AB32: =IFERROR(((N32-D32)/D32)*100,"") | AC32: =IFERROR(((S32-D32)/D32)*100,"") | AD32: =IFERROR(((X32-D32)/D32)*100,"")
E33: =B33*C33 | J33: =G33*H33 | O33: =L33*M33 | T33: =Q33*R33 | Y33: =V33*W33 | AA33: =IFERROR(((I33-D33)/D33)*100,"") | AB33: =IFERROR(((N33-D33)/D33)*100,"") | AC33: =IFERROR(((S33-D33)/D33)*100,"") | AD33: =IFERROR(((X33-D33)/D33)*100,"")
E34: =B34*C34 | J34: =G34*H34 | O34: =L34*M34 | T34: =Q34*R34 | Y34: =V34*W34 | AA34: =IFERROR(((I34-D34)/D34)*100,"") | AB34: =IFERROR(((N34-D34)/D34)*100,"") | AC34: =IFERROR(((S34-D34)/D34)*100,"") | AD34: =IFERROR(((X34-D34)/D34)*100,"") | AM34: =AG34*AG33 | AN34: =AH34*AH33 | AO34: =AJ34*AJ33 | AP34: =AK34*AK33 | AQ34: =AL34*AL33
E35: PR | J35: PR | O35: PR | T35: PR | AC35: PR-M | AD35: =IFERROR(AVERAGE(G35,L35,Q35,V35),"")
E36: =SUM(E23:E34) | J36: =SUM(J23:J34) | O36: =SUM(O23:O34) | T36: =SUM(T23:T34) | Y36: =SUM(Y23:Y34)
L37: Son | M37: Estr | N37: Fad | O37: Dor | Q37: Média | T37: Teste de potência
A38: QUARTA-FEIRA | C38: DATA | Q38: =IFERROR(AVERAGE(L38:O38),"") | S38: =Q38
A39: Exercícios | B39: série 1 | G39: série 2 | L39: série 3 | Q39: série 4 | V39: série 5 | AA39: VEL (2x1) | AB39: VEL (3x1) | AC39: VEL (4x1) | AD39: VEL (5x1) | AG39: VTT-SESSÃO | AJ39: CARGA DE TREINO (U.A)
B40: nº reps | C40: peso(kg) | D40: veloc(s) | E40: VTT (sér) | G40: nº reps | H40: peso(kg) | I40: veloc(s) | J40: VTT (sér) | L40: nº reps | M40: peso(kg) | N40: veloc(s) | O40: VTT (sér) | Q40: nº reps | R40: peso(kg) | S40: veloc(s) | T40: VTT (sér) | V40: nº reps | W40: peso(kg) | X40: veloc(s) | Y40: VTT (sér) | AG40: =SUM(E54+J54+O54+T54+Y54) | AJ40: =AE41*AG43
...

Sheet SEM 2
A1: SEMANA 2 | L1: Son | M1: Estr | N1: Fad | O1: Dor | Q1: Média | T1: Teste de potência
A2: SEGUNDA-FEIRA | C2: DATA | Q2: =IFERROR(AVERAGE(L2:O2),"") | S2: =Q2
A3: Exercícios | B3: série 1 | G3: série 2 | L3: série 3 | Q3: série 4 | V3: série 5 | AA3: VEL (2x1) | AB3: VEL (3x1) | AC3: VEL (4x1) | AD3: VEL (5x1) | AG3: VTT-SESSÃO | AJ3: CARGA DE TREINO (U.A)
B4: nº reps | C4: peso(kg) | D4: veloc(s) | E4: VTT (sér) | G4: nº reps | H4: peso(kg) | I4: veloc(s) | J4: VTT (sér) | L4: nº reps | M4: peso(kg) | N4: veloc(s) | O4: VTT (sér) | Q4: nº reps | R4: peso(kg) | S4: veloc(s) | T4: VTT (sér) | V4: nº reps | W4: peso(kg) | X4: veloc(s) | Y4: VTT (sér) | AG4: =SUM(E18+J18+O18+T18+Y18) | AJ4: =AE5*AG7
E5: =B5*C5 | J5: =G5*H5 | O5: =L5*M5 | T5: =Q5*R5 | Y5: =V5*W5 | AA5: =IFERROR(((I5-D5)/D5)*100,"") | AB5: =IFERROR(((N5-D5)/D5)*100,"") | AC5: =IFERROR(((S5-D5)/D5)*100,"") | AD5: =IFERROR(((X5-D5)/D5)*100,"")
A6: Cadeira Abdutora 90° | E6: =B6*C6 | J6: =G6*H6 | O6: =L6*M6 | T6: =Q6*R6 | Y6: =V6*W6 | AA6: =IFERROR(((I6-D6)/D6)*100,"") | AB6: =IFERROR(((N6-D6)/D6)*100,"") | AC6: =IFERROR(((S6-D6)/D6)*100,"") | AD6: =IFERROR(((X6-D6)/D6)*100,"") | AG6: Tempo total sessão (min)
A7: Elevação Pélvica (livre/máq) | E7: =B7*C7 | J7: =G7*H7 | O7: =L7*M7 | T7: =Q7*R7 | Y7: =V7*W7 | AA7: =IFERROR(((I7-D7)/D7)*100,"") | AB7: =IFERROR(((N7-D7)/D7)*100,"") | AC7: =IFERROR(((S7-D7)/D7)*100,"") | AD7: =IFERROR(((X7-D7)/D7)*100,"")
A8: Afundo no Smith | E8: =B8*C8 | J8: =G8*H8 | O8: =L8*M8 | T8: =Q8*R8 | Y8: =V8*W8 | AA8: =IFERROR(((I8-D8)/D8)*100,"") | AB8: =IFERROR(((N8-D8)/D8)*100,"") | AC8: =IFERROR(((S8-D8)/D8)*100,"") | AD8: =IFERROR(((X8-D8)/D8)*100,"")
A9: Agachamento Livre | E9: =B9*C9 | J9: =G9*H9 | O9: =L9*M9 | T9: =Q9*R9 | Y9: =V9*W9 | AA9: =IFERROR(((I9-D9)/D9)*100,"") | AB9: =IFERROR(((N9-D9)/D9)*100,"") | AC9: =IFERROR(((S9-D9)/D9)*100,"") | AD9: =IFERROR(((X9-D9)/D9)*100,"")
A10: Leg Press 45° | E10: =B10*C10 | J10: =G10*H10 | O10: =L10*M10 | T10: =Q10*R10 | Y10: =V10*W10 | AA10: =IFERROR(((I10-D10)/D10)*100,"") | AB10: =IFERROR(((N10-D10)/D10)*100,"") | AC10: =IFERROR(((S10-D10)/D10)*100,"") | AD10: =IFERROR(((X10-D10)/D10)*100,"")
A11: Cadeira Extensora | E11: =B11*C11 | J11: =G11*H11 | O11: =L11*M11 | T11: =Q11*R11 | Y11: =V11*W11 | AA11: =IFERROR(((I11-D11)/D11)*100,"") | AB11: =IFERROR(((N11-D11)/D11)*100,"") | AC11: =IFERROR(((S11-D11)/D11)*100,"") | AD11: =IFERROR(((X11-D11)/D11)*100,"")
A12: Gêmeos Sentado | E12: =B12*C12 | J12: =G12*H12 | O12: =L12*M12 | T12: =Q12*R12 | Y12: =V12*W12 | AA12: =IFERROR(((I12-D12)/D12)*100,"") | AB12: =IFERROR(((N12-D12)/D12)*100,"") | AC12: =IFERROR(((S12-D12)/D12)*100,"") | AD12: =IFERROR(((X12-D12)/D12)*100,"")
A13: Gêmeos Máquina em Pé | E13: =B13*C13 | J13: =G13*H13 | O13: =L13*M13 | T13: =Q13*R13 | Y13: =V13*W13 | AA13: =IFERROR(((I13-D13)/D13)*100,"") | AB13: =IFERROR(((N13-D13)/D13)*100,"") | AC13: =IFERROR(((S13-D13)/D13)*100,"") | AD13: =IFERROR(((X13-D13)/D13)*100,"")
E14: =B14*C14 | J14: =G14*H14 | O14: =L14*M14 | T14: =Q14*R14 | Y14: =V14*W14 | AA14: =IFERROR(((I14-D14)/D14)*100,"") | AB14: =IFERROR(((N14-D14)/D14)*100,"") | AC14: =IFERROR(((S14-D14)/D14)*100,"") | AD14: =IFERROR(((X14-D14)/D14)*100,"")
E15: =B15*C15 | J15: =G15*H15 | O15: =L15*M15 | T15: =Q15*R15 | Y15: =V15*W15 | AA15: =IFERROR(((I15-D15)/D15)*100,"") | AB15: =IFERROR(((N15-D15)/D15)*100,"") | AC15: =IFERROR(((S15-D15)/D15)*100,"") | AD15: =IFERROR(((X15-D15)/D15)*100,"")
E16: =B16*C16 | J16: =G16*H16 | O16: =L16*M16 | T16: =Q16*R16 | Y16: =V16*W16 | AA16: =IFERROR(((I16-D16)/D16)*100,"") | AB16: =IFERROR(((N16-D16)/D16)*100,"") | AC16: =IFERROR(((S16-D16)/D16)*100,"") | AD16: =IFERROR(((X16-D16)/D16)*100,"") | AN16: =AH16*AH15 | AO16: =AJ16*AJ15 | AP16: =AK16*AK15 | AQ16: =AL16*AL15
E17: PR | J17: PR | O17: PR | T17: PR | AC17: PR-M | AD17: =IFERROR(AVERAGE(G17,L17,Q17,V17),"")
E18: =SUM(E5:E16) | J18: =SUM(J5:J16) | O18: =SUM(O5:O16) | T18: =SUM(T5:T16) | Y18: =SUM(Y5:Y16)
L19: Son | M19: Estr | N19: Fad | O19: Dor | Q19: Média | T19: Teste de potência
A20: TERÇA-FEIRA | C20: DATA | Q20: =IFERROR(AVERAGE(L20:O20),"") | S20: =Q20
A21: Exercícios | B21: série 1 | G21: série 2 | L21: série 3 | Q21: série 4 | V21: série 5 | AA21: VEL (2x1) | AB21: VEL (3x1) | AC21: VEL (4x1) | AD21: VEL (5x1) | AG21: VTT-SESSÃO | AJ21: CARGA DE TREINO (U.A)
B22: nº reps | C22: peso(kg) | D22: veloc(s) | E22: VTT (sér) | G22: nº reps | H22: peso(kg) | I22: veloc(s) | J22: VTT (sér) | L22: nº reps | M22: peso(kg) | N22: veloc(s) | O22: VTT (sér) | Q22: nº reps | R22: peso(kg) | S22: veloc(s) | T22: VTT (sér) | V22: nº reps | W22: peso(kg) | X22: veloc(s) | Y22: VTT (sér) | AG22: =SUM(E36+J36+O36+T36+Y36) | AJ22: =AE23*AG25
E23: =B23*C23 | J23: =G23*H23 | O23: =L23*M23 | T23: =Q23*R23 | Y23: =V23*W23 | AA23: =IFERROR(((I23-D23)/D23)*100,"") | AB23: =IFERROR(((N23-D23)/D23)*100,"") | AC23: =IFERROR(((S23-D23)/D23)*100,"") | AD23: =IFERROR(((X23-D23)/D23)*100,"")
A24: Supino Inclinado Smith 30° | E24: =B24*C24 | J24: =G24*H24 | O24: =L24*M24 | T24: =Q24*R24 | Y24: =V24*W24 | AA24: =IFERROR(((I24-D24)/D24)*100,"") | AB24: =IFERROR(((N24-D24)/D24)*100,"") | AC24: =IFERROR(((S24-D24)/D24)*100,"") | AD24: =IFERROR(((X24-D24)/D24)*100,"") | AG24: Tempo total sessão (min)
A25: Fly Inclinado Banco 30° | E25: =B25*C25 | J25: =G25*H25 | O25: =L25*M25 | T25: =Q25*R25 | Y25: =V25*W25 | AA25: =IFERROR(((I25-D25)/D25)*100,"") | AB25: =IFERROR(((N25-D25)/D25)*100,"") | AC25: =IFERROR(((S25-D25)/D25)*100,"") | AD25: =IFERROR(((X25-D25)/D25)*100,"")
A26: Fly Reto | E26: =B26*C26 | J26: =G26*H26 | O26: =L26*M26 | T26: =Q26*R26 | Y26: =V26*W26 | AA26: =IFERROR(((I26-D26)/D26)*100,"") | AB26: =IFERROR(((N26-D26)/D26)*100,"") | AC26: =IFERROR(((S26-D26)/D26)*100,"") | AD26: =IFERROR(((X26-D26)/D26)*100,"")
A27: Cross-over | E27: =B27*C27 | J27: =G27*H27 | O27: =L27*M27 | T27: =Q27*R27 | Y27: =V27*W27 | AA27: =IFERROR(((I27-D27)/D27)*100,"") | AB27: =IFERROR(((N27-D27)/D27)*100,"") | AC27: =IFERROR(((S27-D27)/D27)*100,"") | AD27: =IFERROR(((X27-D27)/D27)*100,"")
A28: Crucifixo em Máquina | E28: =B28*C28 | J28: =G28*H28 | O28: =L28*M28 | T28: =Q28*R28 | Y28: =V28*W28 | AA28: =IFERROR(((I28-D28)/D28)*100,"") | AB28: =IFERROR(((N28-D28)/D28)*100,"") | AC28: =IFERROR(((S28-D28)/D28)*100,"") | AD28: =IFERROR(((X28-D28)/D28)*100,"")
A29: Elevação Frontal Corda | E29: =B29*C29 | J29: =G29*H29 | O29: =L29*M29 | T29: =Q29*R29 | Y29: =V29*W29 | AA29: =IFERROR(((I29-D29)/D29)*100,"") | AB29: =IFERROR(((N29-D29)/D29)*100,"") | AC29: =IFERROR(((S29-D29)/D29)*100,"") | AD29: =IFERROR(((X29-D29)/D29)*100,"")
A30: Flexão Quadril/Coluna Paralelas | E30: =B30*C30 | J30: =G30*H30 | O30: =L30*M30 | T30: =Q30*R30 | Y30: =V30*W30 | AA30: =IFERROR(((I30-D30)/D30)*100,"") | AB30: =IFERROR(((N30-D30)/D30)*100,"") | AC30: =IFERROR(((S30-D30)/D30)*100,"") | AD30: =IFERROR(((X30-D30)/D30)*100,"")
A31: Flexão de Coluna Máquina | E31: =B31*C31 | J31: =G31*H31 | O31: =L31*M31 | T31: =Q31*R31 | Y31: =V31*W31 | AA31: =IFERROR(((I31-D31)/D31)*100,"") | AB31: =IFERROR(((N31-D31)/D31)*100,"") | AC31: =IFERROR(((S31-D31)/D31)*100,"") | AD31: =IFERROR(((X31-D31)/D31)*100,"")
E32: =B32*C32 | J32: =G32*H32 | O32: =L32*M32 | T32: =Q32*R32 | Y32: =V32*W32 | AA32: =IFERROR(((I32-D32)/D32)*100,"") | AB32: =IFERROR(((N32-D32)/D32)*100,"") | AC32: =IFERROR(((S32-D32)/D32)*100,"") | AD32: =IFERROR(((X32-D32)/D32)*100,"")
E33: =B33*C33 | J33: =G33*H33 | O33: =L33*M33 | T33: =Q33*R33 | Y33: =V33*W33 | AA33: =IFERROR(((I33-D33)/D33)*100,"") | AB33: =IFERROR(((N33-D33)/D33)*100,"") | AC33: =IFERROR(((S33-D33)/D33)*100,"") | AD33: =IFERROR(((X33-D33)/D33)*100,"")
E34: =B34*C34 | J34: =G34*H34 | O34: =L34*M34 | T34: =Q34*R34 | Y34: =V34*W34 | AA34: =IFERROR(((I34-D34)/D34)*100,"") | AB34: =IFERROR(((N34-D34)/D34)*100,"") | AC34: =IFERROR(((S34-D34)/D34)*100,"") | AD34: =IFERROR(((X34-D34)/D34)*100,"") | AM34: =AG34*AG33 | AN34: =AH34*AH33 | AO34: =AJ34*AJ33 | AP34: =AK34*AK33 | AQ34: =AL34*AL33
E35: PR | J35: PR | O35: PR | T35: PR | AC35: PR-M | AD35: =IFERROR(AVERAGE(G35,L35,Q35,V35),"")
E36: =SUM(E23:E34) | J36: =SUM(J23:J34) | O36: =SUM(O23:O34) | T36: =SUM(T23:T34) | Y36: =SUM(Y23:Y34)
L37: Son | M37: Estr | N37: Fad | O37: Dor | Q37: Média | T37: Teste de potência
A38: QUARTA-FEIRA | C38: DATA | Q38: =IFERROR(AVERAGE(L38:O38),"") | S38: =Q38
A39: Exercícios | B39: série 1 | G39: série 2 | L39: série 3 | Q39: série 4 | V39: série 5 | AA39: VEL (2x1) | AB39: VEL (3x1) | AC39: VEL (4x1) | AD39: VEL (5x1) | AG39: VTT-SESSÃO | AJ39: CARGA DE TREINO (U.A)
B40: nº reps | C40: peso(kg) | D40: veloc(s) | E40: VTT (sér) | G40: nº reps | H40: peso(kg) | I40: veloc(s) | J40: VTT (sér) | L40: nº reps | M40: peso(kg) | N40: veloc(s) | O40: VTT (sér) | Q40: nº reps | R40: peso(kg) | S40: veloc(s) | T40: VTT (sér) | V40: nº reps | W40: peso(kg) | X40: veloc(s) | Y40: VTT (sér) | AG40: =SUM(E54+J54+O54+T54+Y54) | AJ40: =AE41*AG43
...

Sheet SEM 3
A1: SEMANA 3 | L1: Son | M1: Estr | N1: Fad | O1: Dor | Q1: Média | T1: Teste de potência
A2: SEGUNDA-FEIRA | C2: DATA | Q2: =IFERROR(AVERAGE(L2:O2),"") | S2: =Q2
A3: Exercícios | B3: série 1 | G3: série 2 | L3: série 3 | Q3: série 4 | V3: série 5 | AA3: VEL (2x1) | AB3: VEL (3x1) | AC3: VEL (4x1) | AD3: VEL (5x1) | AG3: VTT-SESSÃO | AJ3: CARGA DE TREINO (U.A)
B4: nº reps | C4: peso(kg) | D4: veloc(s) | E4: VTT (sér) | G4: nº reps | H4: peso(kg) | I4: veloc(s) | J4: VTT (sér) | L4: nº reps | M4: peso(kg) | N4: veloc(s) | O4: VTT (sér) | Q4: nº reps | R4: peso(kg) | S4: veloc(s) | T4: VTT (sér) | V4: nº reps | W4: peso(kg) | X4: veloc(s) | Y4: VTT (sér) | AG4: =SUM(E18+J18+O18+T18+Y18) | AJ4: =AE5*AG7
E5: =B5*C5 | J5: =G5*H5 | O5: =L5*M5 | T5: =Q5*R5 | Y5: =V5*W5 | AA5: =IFERROR(((I5-D5)/D5)*100,"") | AB5: =IFERROR(((N5-D5)/D5)*100,"") | AC5: =IFERROR(((S5-D5)/D5)*100,"") | AD5: =IFERROR(((X5-D5)/D5)*100,"")
A6: Cadeira Abdutora 90° | E6: =B6*C6 | J6: =G6*H6 | O6: =L6*M6 | T6: =Q6*R6 | Y6: =V6*W6 | AA6: =IFERROR(((I6-D6)/D6)*100,"") | AB6: =IFERROR(((N6-D6)/D6)*100,"") | AC6: =IFERROR(((S6-D6)/D6)*100,"") | AD6: =IFERROR(((X6-D6)/D6)*100,"") | AG6: Tempo total sessão (min)
A7: Elevação Pélvica (livre/máq) | E7: =B7*C7 | J7: =G7*H7 | O7: =L7*M7 | T7: =Q7*R7 | Y7: =V7*W7 | AA7: =IFERROR(((I7-D7)/D7)*100,"") | AB7: =IFERROR(((N7-D7)/D7)*100,"") | AC7: =IFERROR(((S7-D7)/D7)*100,"") | AD7: =IFERROR(((X7-D7)/D7)*100,"")
A8: Afundo no Smith | E8: =B8*C8 | J8: =G8*H8 | O8: =L8*M8 | T8: =Q8*R8 | Y8: =V8*W8 | AA8: =IFERROR(((I8-D8)/D8)*100,"") | AB8: =IFERROR(((N8-D8)/D8)*100,"") | AC8: =IFERROR(((S8-D8)/D8)*100,"") | AD8: =IFERROR(((X8-D8)/D8)*100,"")
A9: Agachamento Livre | E9: =B9*C9 | J9: =G9*H9 | O9: =L9*M9 | T9: =Q9*R9 | Y9: =V9*W9 | AA9: =IFERROR(((I9-D9)/D9)*100,"") | AB9: =IFERROR(((N9-D9)/D9)*100,"") | AC9: =IFERROR(((S9-D9)/D9)*100,"") | AD9: =IFERROR(((X9-D9)/D9)*100,"")
A10: Leg Press 45° | E10: =B10*C10 | J10: =G10*H10 | O10: =L10*M10 | T10: =Q10*R10 | Y10: =V10*W10 | AA10: =IFERROR(((I10-D10)/D10)*100,"") | AB10: =IFERROR(((N10-D10)/D10)*100,"") | AC10: =IFERROR(((S10-D10)/D10)*100,"") | AD10: =IFERROR(((X10-D10)/D10)*100,"")
A11: Cadeira Extensora | E11: =B11*C11 | J11: =G11*H11 | O11: =L11*M11 | T11: =Q11*R11 | Y11: =V11*W11 | AA11: =IFERROR(((I11-D11)/D11)*100,"") | AB11: =IFERROR(((N11-D11)/D11)*100,"") | AC11: =IFERROR(((S11-D11)/D11)*100,"") | AD11: =IFERROR(((X11-D11)/D11)*100,"")
A12: Gêmeos Sentado | E12: =B12*C12 | J12: =G12*H12 | O12: =L12*M12 | T12: =Q12*R12 | Y12: =V12*W12 | AA12: =IFERROR(((I12-D12)/D12)*100,"") | AB12: =IFERROR(((N12-D12)/D12)*100,"") | AC12: =IFERROR(((S12-D12)/D12)*100,"") | AD12: =IFERROR(((X12-D12)/D12)*100,"")
A13: Gêmeos Máquina em Pé | E13: =B13*C13 | J13: =G13*H13 | O13: =L13*M13 | T13: =Q13*R13 | Y13: =V13*W13 | AA13: =IFERROR(((I13-D13)/D13)*100,"") | AB13: =IFERROR(((N13-D13)/D13)*100,"") | AC13: =IFERROR(((S13-D13)/D13)*100,"") | AD13: =IFERROR(((X13-D13)/D13)*100,"")
E14: =B14*C14 | J14: =G14*H14 | O14: =L14*M14 | T14: =Q14*R14 | Y14: =V14*W14 | AA14: =IFERROR(((I14-D14)/D14)*100,"") | AB14: =IFERROR(((N14-D14)/D14)*100,"") | AC14: =IFERROR(((S14-D14)/D14)*100,"") | AD14: =IFERROR(((X14-D14)/D14)*100,"")
E15: =B15*C15 | J15: =G15*H15 | O15: =L15*M15 | T15: =Q15*R15 | Y15: =V15*W15 | AA15: =IFERROR(((I15-D15)/D15)*100,"") | AB15: =IFERROR(((N15-D15)/D15)*100,"") | AC15: =IFERROR(((S15-D15)/D15)*100,"") | AD15: =IFERROR(((X15-D15)/D15)*100,"")
E16: =B16*C16 | J16: =G16*H16 | O16: =L16*M16 | T16: =Q16*R16 | Y16: =V16*W16 | AA16: =IFERROR(((I16-D16)/D16)*100,"") | AB16: =IFERROR(((N16-D16)/D16)*100,"") | AC16: =IFERROR(((S16-D16)/D16)*100,"") | AD16: =IFERROR(((X16-D16)/D16)*100,"") | AN16: =AH16*AH15 | AO16: =AJ16*AJ15 | AP16: =AK16*AK15 | AQ16: =AL16*AL15
E17: PR | J17: PR | O17: PR | T17: PR | AC17: PR-M | AD17: =IFERROR(AVERAGE(G17,L17,Q17,V17),"")
E18: =SUM(E5:E16) | J18: =SUM(J5:J16) | O18: =SUM(O5:O16) | T18: =SUM(T5:T16) | Y18: =SUM(Y5:Y16)
L19: Son | M19: Estr | N19: Fad | O19: Dor | Q19: Média | T19: Teste de potência
A20: TERÇA-FEIRA | C20: DATA | Q20: =IFERROR(AVERAGE(L20:O20),"") | S20: =Q20
A21: Exercícios | B21: série 1 | G21: série 2 | L21: série 3 | Q21: série 4 | V21: série 5 | AA21: VEL (2x1) | AB21: VEL (3x1) | AC21: VEL (4x1) | AD21: VEL (5x1) | AG21: VTT-SESSÃO | AJ21: CARGA DE TREINO (U.A)
B22: nº reps | C22: peso(kg) | D22: veloc(s) | E22: VTT (sér) | G22: nº reps | H22: peso(kg) | I22: veloc(s) | J22: VTT (sér) | L22: nº reps | M22: peso(kg) | N22: veloc(s) | O22: VTT (sér) | Q22: nº reps | R22: peso(kg) | S22: veloc(s) | T22: VTT (sér) | V22: nº reps | W22: peso(kg) | X22: veloc(s) | Y22: VTT (sér) | AG22: =SUM(E36+J36+O36+T36+Y36) | AJ22: =AE23*AG25
E23: =B23*C23 | J23: =G23*H23 | O23: =L23*M23 | T23: =Q23*R23 | Y23: =V23*W23 | AA23: =IFERROR(((I23-D23)/D23)*100,"") | AB23: =IFERROR(((N23-D23)/D23)*100,"") | AC23: =IFERROR(((S23-D23)/D23)*100,"") | AD23: =IFERROR(((X23-D23)/D23)*100,"")
A24: Supino Inclinado Smith 30° | E24: =B24*C24 | J24: =G24*H24 | O24: =L24*M24 | T24: =Q24*R24 | Y24: =V24*W24 | AA24: =IFERROR(((I24-D24)/D24)*100,"") | AB24: =IFERROR(((N24-D24)/D24)*100,"") | AC24: =IFERROR(((S24-D24)/D24)*100,"") | AD24: =IFERROR(((X24-D24)/D24)*100,"") | AG24: Tempo total sessão (min)
A25: Fly Inclinado Banco 30° | E25: =B25*C25 | J25: =G25*H25 | O25: =L25*M25 | T25: =Q25*R25 | Y25: =V25*W25 | AA25: =IFERROR(((I25-D25)/D25)*100,"") | AB25: =IFERROR(((N25-D25)/D25)*100,"") | AC25: =IFERROR(((S25-D25)/D25)*100,"") | AD25: =IFERROR(((X25-D25)/D25)*100,"")
A26: Fly Reto | E26: =B26*C26 | J26: =G26*H26 | O26: =L26*M26 | T26: =Q26*R26 | Y26: =V26*W26 | AA26: =IFERROR(((I26-D26)/D26)*100,"") | AB26: =IFERROR(((N26-D26)/D26)*100,"") | AC26: =IFERROR(((S26-D26)/D26)*100,"") | AD26: =IFERROR(((X26-D26)/D26)*100,"")
A27: Cross-over | E27: =B27*C27 | J27: =G27*H27 | O27: =L27*M27 | T27: =Q27*R27 | Y27: =V27*W27 | AA27: =IFERROR(((I27-D27)/D27)*100,"") | AB27: =IFERROR(((N27-D27)/D27)*100,"") | AC27: =IFERROR(((S27-D27)/D27)*100,"") | AD27: =IFERROR(((X27-D27)/D27)*100,"")
A28: Crucifixo em Máquina | E28: =B28*C28 | J28: =G28*H28 | O28: =L28*M28 | T28: =Q28*R28 | Y28: =V28*W28 | AA28: =IFERROR(((I28-D28)/D28)*100,"") | AB28: =IFERROR(((N28-D28)/D28)*100,"") | AC28: =IFERROR(((S28-D28)/D28)*100,"") | AD28: =IFERROR(((X28-D28)/D28)*100,"")
A29: Elevação Frontal Corda | E29: =B29*C29 | J29: =G29*H29 | O29: =L29*M29 | T29: =Q29*R29 | Y29: =V29*W29 | AA29: =IFERROR(((I29-D29)/D29)*100,"") | AB29: =IFERROR(((N29-D29)/D29)*100,"") | AC29: =IFERROR(((S29-D29)/D29)*100,"") | AD29: =IFERROR(((X29-D29)/D29)*100,"")
A30: Flexão Quadril/Coluna Paralelas | E30: =B30*C30 | J30: =G30*H30 | O30: =L30*M30 | T30: =Q30*R30 | Y30: =V30*W30 | AA30: =IFERROR(((I30-D30)/D30)*100,"") | AB30: =IFERROR(((N30-D30)/D30)*100,"") | AC30: =IFERROR(((S30-D30)/D30)*100,"") | AD30: =IFERROR(((X30-D30)/D30)*100,"")
A31: Flexão de Coluna Máquina | E31: =B31*C31 | J31: =G31*H31 | O31: =L31*M31 | T31: =Q31*R31 | Y31: =V31*W31 | AA31: =IFERROR(((I31-D31)/D31)*100,"") | AB31: =IFERROR(((N31-D31)/D31)*100,"") | AC31: =IFERROR(((S31-D31)/D31)*100,"") | AD31: =IFERROR(((X31-D31)/D31)*100,"")
E32: =B32*C32 | J32: =G32*H32 | O32: =L32*M32 | T32: =Q32*R32 | Y32: =V32*W32 | AA32: =IFERROR(((I32-D32)/D32)*100,"") | AB32: =IFERROR(((N32-D32)/D32)*100,"") | AC32: =IFERROR(((S32-D32)/D32)*100,"") | AD32: =IFERROR(((X32-D32)/D32)*100,"")
E33: =B33*C33 | J33: =G33*H33 | O33: =L33*M33 | T33: =Q33*R33 | Y33: =V33*W33 | AA33: =IFERROR(((I33-D33)/D33)*100,"") | AB33: =IFERROR(((N33-D33)/D33)*100,"") | AC33: =IFERROR(((S33-D33)/D33)*100,"") | AD33: =IFERROR(((X33-D33)/D33)*100,"")
E34: =B34*C34 | J34: =G34*H34 | O34: =L34*M34 | T34: =Q34*R34 | Y34: =V34*W34 | AA34: =IFERROR(((I34-D34)/D34)*100,"") | AB34: =IFERROR(((N34-D34)/D34)*100,"") | AC34: =IFERROR(((S34-D34)/D34)*100,"") | AD34: =IFERROR(((X34-D34)/D34)*100,"") | AM34: =AG34*AG33 | AN34: =AH34*AH33 | AO34: =AJ34*AJ33 | AP34: =AK34*AK33 | AQ34: =AL34*AL33
E35: PR | J35: PR | O35: PR | T35: PR | AC35: PR-M | AD35: =IFERROR(AVERAGE(G35,L35,Q35,V35),"")
E36: =SUM(E23:E34) | J36: =SUM(J23:J34) | O36: =SUM(O23:O34) | T36: =SUM(T23:T34) | Y36: =SUM(Y23:Y34)
L37: Son | M37: Estr | N37: Fad | O37: Dor | Q37: Média | T37: Teste de potência
A38: QUARTA-FEIRA | C38: DATA | Q38: =IFERROR(AVERAGE(L38:O38),"") | S38: =Q38
A39: Exercícios | B39: série 1 | G39: série 2 | L39: série 3 | Q39: série 4 | V39: série 5 | AA39: VEL (2x1) | AB39: VEL (3x1) | AC39: VEL (4x1) | AD39: VEL (5x1) | AG39: VTT-SESSÃO | AJ39: CARGA DE TREINO (U.A)
B40: nº reps | C40: peso(kg) | D40: veloc(s) | E40: VTT (sér) | G40: nº reps | H40: peso(kg) | I40: veloc(s) | J40: VTT (sér) | L40: nº reps | M40: peso(kg) | N40: veloc(s) | O40: VTT (sér) | Q40: nº reps | R40: peso(kg) | S40: veloc(s) | T40: VTT (sér) | V40: nº reps | W40: peso(kg) | X40: veloc(s) | Y40: VTT (sér) | AG40: =SUM(E54+J54+O54+T54+Y54) | AJ40: =AE41*AG43
...

Sheet SEM 4
A1: SEMANA 4 | L1: Son | M1: Estr | N1: Fad | O1: Dor | Q1: Média | T1: Teste de potência
A2: SEGUNDA-FEIRA | C2: DATA | Q2: =IFERROR(AVERAGE(L2:O2),"") | S2: =Q2
A3: Exercícios | B3: série 1 | G3: série 2 | L3: série 3 | Q3: série 4 | V3: série 5 | AA3: VEL (2x1) | AB3: VEL (3x1) | AC3: VEL (4x1) | AD3: VEL (5x1) | AG3: VTT-SESSÃO | AJ3: CARGA DE TREINO (U.A)
B4: nº reps | C4: peso(kg) | D4: veloc(s) | E4: VTT (sér) | G4: nº reps | H4: peso(kg) | I4: veloc(s) | J4: VTT (sér) | L4: nº reps | M4: peso(kg) | N4: veloc(s) | O4: VTT (sér) | Q4: nº reps | R4: peso(kg) | S4: veloc(s) | T4: VTT (sér) | V4: nº reps | W4: peso(kg) | X4: veloc(s) | Y4: VTT (sér) | AG4: =SUM(E18+J18+O18+T18+Y18) | AJ4: =AE5*AG7
E5: =B5*C5 | J5: =G5*H5 | O5: =L5*M5 | T5: =Q5*R5 | Y5: =V5*W5 | AA5: =IFERROR(((I5-D5)/D5)*100,"") | AB5: =IFERROR(((N5-D5)/D5)*100,"") | AC5: =IFERROR(((S5-D5)/D5)*100,"") | AD5: =IFERROR(((X5-D5)/D5)*100,"")
A6: Cadeira Abdutora 90° | E6: =B6*C6 | J6: =G6*H6 | O6: =L6*M6 | T6: =Q6*R6 | Y6: =V6*W6 | AA6: =IFERROR(((I6-D6)/D6)*100,"") | AB6: =IFERROR(((N6-D6)/D6)*100,"") | AC6: =IFERROR(((S6-D6)/D6)*100,"") | AD6: =IFERROR(((X6-D6)/D6)*100,"") | AG6: Tempo total sessão (min)
A7: Elevação Pélvica (livre/máq) | E7: =B7*C7 | J7: =G7*H7 | O7: =L7*M7 | T7: =Q7*R7 | Y7: =V7*W7 | AA7: =IFERROR(((I7-D7)/D7)*100,"") | AB7: =IFERROR(((N7-D7)/D7)*100,"") | AC7: =IFERROR(((S7-D7)/D7)*100,"") | AD7: =IFERROR(((X7-D7)/D7)*100,"")
A8: Afundo no Smith | E8: =B8*C8 | J8: =G8*H8 | O8: =L8*M8 | T8: =Q8*R8 | Y8: =V8*W8 | AA8: =IFERROR(((I8-D8)/D8)*100,"") | AB8: =IFERROR(((N8-D8)/D8)*100,"") | AC8: =IFERROR(((S8-D8)/D8)*100,"") | AD8: =IFERROR(((X8-D8)/D8)*100,"")
A9: Agachamento Livre | E9: =B9*C9 | J9: =G9*H9 | O9: =L9*M9 | T9: =Q9*R9 | Y9: =V9*W9 | AA9: =IFERROR(((I9-D9)/D9)*100,"") | AB9: =IFERROR(((N9-D9)/D9)*100,"") | AC9: =IFERROR(((S9-D9)/D9)*100,"") | AD9: =IFERROR(((X9-D9)/D9)*100,"")
A10: Leg Press 45° | E10: =B10*C10 | J10: =G10*H10 | O10: =L10*M10 | T10: =Q10*R10 | Y10: =V10*W10 | AA10: =IFERROR(((I10-D10)/D10)*100,"") | AB10: =IFERROR(((N10-D10)/D10)*100,"") | AC10: =IFERROR(((S10-D10)/D10)*100,"") | AD10: =IFERROR(((X10-D10)/D10)*100,"")
A11: Cadeira Extensora | E11: =B11*C11 | J11: =G11*H11 | O11: =L11*M11 | T11: =Q11*R11 | Y11: =V11*W11 | AA11: =IFERROR(((I11-D11)/D11)*100,"") | AB11: =IFERROR(((N11-D11)/D11)*100,"") | AC11: =IFERROR(((S11-D11)/D11)*100,"") | AD11: =IFERROR(((X11-D11)/D11)*100,"")
A12: Gêmeos Sentado | E12: =B12*C12 | J12: =G12*H12 | O12: =L12*M12 | T12: =Q12*R12 | Y12: =V12*W12 | AA12: =IFERROR(((I12-D12)/D12)*100,"") | AB12: =IFERROR(((N12-D12)/D12)*100,"") | AC12: =IFERROR(((S12-D12)/D12)*100,"") | AD12: =IFERROR(((X12-D12)/D12)*100,"")
A13: Gêmeos Máquina em Pé | E13: =B13*C13 | J13: =G13*H13 | O13: =L13*M13 | T13: =Q13*R13 | Y13: =V13*W13 | AA13: =IFERROR(((I13-D13)/D13)*100,"") | AB13: =IFERROR(((N13-D13)/D13)*100,"") | AC13: =IFERROR(((S13-D13)/D13)*100,"") | AD13: =IFERROR(((X13-D13)/D13)*100,"")
E14: =B14*C14 | J14: =G14*H14 | O14: =L14*M14 | T14: =Q14*R14 | Y14: =V14*W14 | AA14: =IFERROR(((I14-D14)/D14)*100,"") | AB14: =IFERROR(((N14-D14)/D14)*100,"") | AC14: =IFERROR(((S14-D14)/D14)*100,"") | AD14: =IFERROR(((X14-D14)/D14)*100,"")
E15: =B15*C15 | J15: =G15*H15 | O15: =L15*M15 | T15: =Q15*R15 | Y15: =V15*W15 | AA15: =IFERROR(((I15-D15)/D15)*100,"") | AB15: =IFERROR(((N15-D15)/D15)*100,"") | AC15: =IFERROR(((S15-D15)/D15)*100,"") | AD15: =IFERROR(((X15-D15)/D15)*100,"")
E16: =B16*C16 | J16: =G16*H16 | O16: =L16*M16 | T16: =Q16*R16 | Y16: =V16*W16 | AA16: =IFERROR(((I16-D16)/D16)*100,"") | AB16: =IFERROR(((N16-D16)/D16)*100,"") | AC16: =IFERROR(((S16-D16)/D16)*100,"") | AD16: =IFERROR(((X16-D16)/D16)*100,"") | AN16: =AH16*AH15 | AO16: =AJ16*AJ15 | AP16: =AK16*AK15 | AQ16: =AL16*AL15
E17: PR | J17: PR | O17: PR | T17: PR | AC17: PR-M | AD17: =IFERROR(AVERAGE(G17,L17,Q17,V17),"")
E18: =SUM(E5:E16) | J18: =SUM(J5:J16) | O18: =SUM(O5:O16) | T18: =SUM(T5:T16) | Y18: =SUM(Y5:Y16)
L19: Son | M19: Estr | N19: Fad | O19: Dor | Q19: Média | T19: Teste de potência
A20: TERÇA-FEIRA | C20: DATA | Q20: =IFERROR(AVERAGE(L20:O20),"") | S20: =Q20
A21: Exercícios | B21: série 1 | G21: série 2 | L21: série 3 | Q21: série 4 | V21: série 5 | AA21: VEL (2x1) | AB21: VEL (3x1) | AC21: VEL (4x1) | AD21: VEL (5x1) | AG21: VTT-SESSÃO | AJ21: CARGA DE TREINO (U.A)
B22: nº reps | C22: peso(kg) | D22: veloc(s) | E22: VTT (sér) | G22: nº reps | H22: peso(kg) | I22: veloc(s) | J22: VTT (sér) | L22: nº reps | M22: peso(kg) | N22: veloc(s) | O22: VTT (sér) | Q22: nº reps | R22: peso(kg) | S22: veloc(s) | T22: VTT (sér) | V22: nº reps | W22: peso(kg) | X22: veloc(s) | Y22: VTT (sér) | AG22: =SUM(E36+J36+O36+T36+Y36) | AJ22: =AE23*AG25
E23: =B23*C23 | J23: =G23*H23 | O23: =L23*M23 | T23: =Q23*R23 | Y23: =V23*W23 | AA23: =IFERROR(((I23-D23)/D23)*100,"") | AB23: =IFERROR(((N23-D23)/D23)*100,"") | AC23: =IFERROR(((S23-D23)/D23)*100,"") | AD23: =IFERROR(((X23-D23)/D23)*100,"")
A24: Supino Inclinado Smith 30° | E24: =B24*C24 | J24: =G24*H24 | O24: =L24*M24 | T24: =Q24*R24 | Y24: =V24*W24 | AA24: =IFERROR(((I24-D24)/D24)*100,"") | AB24: =IFERROR(((N24-D24)/D24)*100,"") | AC24: =IFERROR(((S24-D24)/D24)*100,"") | AD24: =IFERROR(((X24-D24)/D24)*100,"") | AG24: Tempo total sessão (min)
A25: Fly Inclinado Banco 30° | E25: =B25*C25 | J25: =G25*H25 | O25: =L25*M25 | T25: =Q25*R25 | Y25: =V25*W25 | AA25: =IFERROR(((I25-D25)/D25)*100,"") | AB25: =IFERROR(((N25-D25)/D25)*100,"") | AC25: =IFERROR(((S25-D25)/D25)*100,"") | AD25: =IFERROR(((X25-D25)/D25)*100,"")
A26: Fly Reto | E26: =B26*C26 | J26: =G26*H26 | O26: =L26*M26 | T26: =Q26*R26 | Y26: =V26*W26 | AA26: =IFERROR(((I26-D26)/D26)*100,"") | AB26: =IFERROR(((N26-D26)/D26)*100,"") | AC26: =IFERROR(((S26-D26)/D26)*100,"") | AD26: =IFERROR(((X26-D26)/D26)*100,"")
A27: Cross-over | E27: =B27*C27 | J27: =G27*H27 | O27: =L27*M27 | T27: =Q27*R27 | Y27: =V27*W27 | AA27: =IFERROR(((I27-D27)/D27)*100,"") | AB27: =IFERROR(((N27-D27)/D27)*100,"") | AC27: =IFERROR(((S27-D27)/D27)*100,"") | AD27: =IFERROR(((X27-D27)/D27)*100,"")
A28: Crucifixo em Máquina | E28: =B28*C28 | J28: =G28*H28 | O28: =L28*M28 | T28: =Q28*R28 | Y28: =V28*W28 | AA28: =IFERROR(((I28-D28)/D28)*100,"") | AB28: =IFERROR(((N28-D28)/D28)*100,"") | AC28: =IFERROR(((S28-D28)/D28)*100,"") | AD28: =IFERROR(((X28-D28)/D28)*100,"")
A29: Elevação Frontal Corda | E29: =B29*C29 | J29: =G29*H29 | O29: =L29*M29 | T29: =Q29*R29 | Y29: =V29*W29 | AA29: =IFERROR(((I29-D29)/D29)*100,"") | AB29: =IFERROR(((N29-D29)/D29)*100,"") | AC29: =IFERROR(((S29-D29)/D29)*100,"") | AD29: =IFERROR(((X29-D29)/D29)*100,"")
A30: Flexão Quadril/Coluna Paralelas | E30: =B30*C30 | J30: =G30*H30 | O30: =L30*M30 | T30: =Q30*R30 | Y30: =V30*W30 | AA30: =IFERROR(((I30-D30)/D30)*100,"") | AB30: =IFERROR(((N30-D30)/D30)*100,"") | AC30: =IFERROR(((S30-D30)/D30)*100,"") | AD30: =IFERROR(((X30-D30)/D30)*100,"")
A31: Flexão de Coluna Máquina | E31: =B31*C31 | J31: =G31*H31 | O31: =L31*M31 | T31: =Q31*R31 | Y31: =V31*W31 | AA31: =IFERROR(((I31-D31)/D31)*100,"") | AB31: =IFERROR(((N31-D31)/D31)*100,"") | AC31: =IFERROR(((S31-D31)/D31)*100,"") | AD31: =IFERROR(((X31-D31)/D31)*100,"")
E32: =B32*C32 | J32: =G32*H32 | O32: =L32*M32 | T32: =Q32*R32 | Y32: =V32*W32 | AA32: =IFERROR(((I32-D32)/D32)*100,"") | AB32: =IFERROR(((N32-D32)/D32)*100,"") | AC32: =IFERROR(((S32-D32)/D32)*100,"") | AD32: =IFERROR(((X32-D32)/D32)*100,"")
E33: =B33*C33 | J33: =G33*H33 | O33: =L33*M33 | T33: =Q33*R33 | Y33: =V33*W33 | AA33: =IFERROR(((I33-D33)/D33)*100,"") | AB33: =IFERROR(((N33-D33)/D33)*100,"") | AC33: =IFERROR(((S33-D33)/D33)*100,"") | AD33: =IFERROR(((X33-D33)/D33)*100,"")
E34: =B34*C34 | J34: =G34*H34 | O34: =L34*M34 | T34: =Q34*R34 | Y34: =V34*W34 | AA34: =IFERROR(((I34-D34)/D34)*100,"") | AB34: =IFERROR(((N34-D34)/D34)*100,"") | AC34: =IFERROR(((S34-D34)/D34)*100,"") | AD34: =IFERROR(((X34-D34)/D34)*100,"") | AM34: =AG34*AG33 | AN34: =AH34*AH33 | AO34: =AJ34*AJ33 | AP34: =AK34*AK33 | AQ34: =AL34*AL33
E35: PR | J35: PR | O35: PR | T35: PR | AC35: PR-M | AD35: =IFERROR(AVERAGE(G35,L35,Q35,V35),"")
E36: =SUM(E23:E34) | J36: =SUM(J23:J34) | O36: =SUM(O23:O34) | T36: =SUM(T23:T34) | Y36: =SUM(Y23:Y34)
L37: Son | M37: Estr | N37: Fad | O37: Dor | Q37: Média | T37: Teste de potência
A38: QUARTA-FEIRA | C38: DATA | Q38: =IFERROR(AVERAGE(L38:O38),"") | S38: =Q38
A39: Exercícios | B39: série 1 | G39: série 2 | L39: série 3 | Q39: série 4 | V39: série 5 | AA39: VEL (2x1) | AB39: VEL (3x1) | AC39: VEL (4x1) | AD39: VEL (5x1) | AG39: VTT-SESSÃO | AJ39: CARGA DE TREINO (U.A)
B40: nº reps | C40: peso(kg) | D40: veloc(s) | E40: VTT (sér) | G40: nº reps | H40: peso(kg) | I40: veloc(s) | J40: VTT (sér) | L40: nº reps | M40: peso(kg) | N40: veloc(s) | O40: VTT (sér) | Q40: nº reps | R40: peso(kg) | S40: veloc(s) | T40: VTT (sér) | V40: nº reps | W40: peso(kg) | X40: veloc(s) | Y40: VTT (sér) | AG40: =SUM(E54+J54+O54+T54+Y54) | AJ40: =AE41*AG43
...

Sheet SEM 5
A1: SEMANA 5 | L1: Son | M1: Estr | N1: Fad | O1: Dor | Q1: Média | T1: Teste de potência
A2: SEGUNDA-FEIRA | C2: DATA | Q2: =IFERROR(AVERAGE(L2:O2),"") | S2: =Q2
A3: Exercícios | B3: série 1 | G3: série 2 | L3: série 3 | Q3: série 4 | V3: série 5 | AA3: VEL (2x1) | AB3: VEL (3x1) | AC3: VEL (4x1) | AD3: VEL (5x1) | AG3: VTT-SESSÃO | AJ3: CARGA DE TREINO (U.A)
B4: nº reps | C4: peso(kg) | D4: veloc(s) | E4: VTT (sér) | G4: nº reps | H4: peso(kg) | I4: veloc(s) | J4: VTT (sér) | L4: nº reps | M4: peso(kg) | N4: veloc(s) | O4: VTT (sér) | Q4: nº reps | R4: peso(kg) | S4: veloc(s) | T4: VTT (sér) | V4: nº reps | W4: peso(kg) | X4: veloc(s) | Y4: VTT (sér) | AG4: =SUM(E18+J18+O18+T18+Y18) | AJ4: =AE5*AG7
E5: =B5*C5 | J5: =G5*H5 | O5: =L5*M5 | T5: =Q5*R5 | Y5: =V5*W5 | AA5: =IFERROR(((I5-D5)/D5)*100,"") | AB5: =IFERROR(((N5-D5)/D5)*100,"") | AC5: =IFERROR(((S5-D5)/D5)*100,"") | AD5: =IFERROR(((X5-D5)/D5)*100,"")
A6: Cadeira Abdutora 90° | E6: =B6*C6 | J6: =G6*H6 | O6: =L6*M6 | T6: =Q6*R6 | Y6: =V6*W6 | AA6: =IFERROR(((I6-D6)/D6)*100,"") | AB6: =IFERROR(((N6-D6)/D6)*100,"") | AC6: =IFERROR(((S6-D6)/D6)*100,"") | AD6: =IFERROR(((X6-D6)/D6)*100,"") | AG6: Tempo total sessão (min)
A7: Elevação Pélvica (livre/máq) | E7: =B7*C7 | J7: =G7*H7 | O7: =L7*M7 | T7: =Q7*R7 | Y7: =V7*W7 | AA7: =IFERROR(((I7-D7)/D7)*100,"") | AB7: =IFERROR(((N7-D7)/D7)*100,"") | AC7: =IFERROR(((S7-D7)/D7)*100,"") | AD7: =IFERROR(((X7-D7)/D7)*100,"")
A8: Afundo no Smith | E8: =B8*C8 | J8: =G8*H8 | O8: =L8*M8 | T8: =Q8*R8 | Y8: =V8*W8 | AA8: =IFERROR(((I8-D8)/D8)*100,"") | AB8: =IFERROR(((N8-D8)/D8)*100,"") | AC8: =IFERROR(((S8-D8)/D8)*100,"") | AD8: =IFERROR(((X8-D8)/D8)*100,"")
A9: Agachamento Livre | E9: =B9*C9 | J9: =G9*H9 | O9: =L9*M9 | T9: =Q9*R9 | Y9: =V9*W9 | AA9: =IFERROR(((I9-D9)/D9)*100,"") | AB9: =IFERROR(((N9-D9)/D9)*100,"") | AC9: =IFERROR(((S9-D9)/D9)*100,"") | AD9: =IFERROR(((X9-D9)/D9)*100,"")
A10: Leg Press 45° | E10: =B10*C10 | J10: =G10*H10 | O10: =L10*M10 | T10: =Q10*R10 | Y10: =V10*W10 | AA10: =IFERROR(((I10-D10)/D10)*100,"") | AB10: =IFERROR(((N10-D10)/D10)*100,"") | AC10: =IFERROR(((S10-D10)/D10)*100,"") | AD10: =IFERROR(((X10-D10)/D10)*100,"")
A11: Cadeira Extensora | E11: =B11*C11 | J11: =G11*H11 | O11: =L11*M11 | T11: =Q11*R11 | Y11: =V11*W11 | AA11: =IFERROR(((I11-D11)/D11)*100,"") | AB11: =IFERROR(((N11-D11)/D11)*100,"") | AC11: =IFERROR(((S11-D11)/D11)*100,"") | AD11: =IFERROR(((X11-D11)/D11)*100,"")
A12: Gêmeos Sentado | E12: =B12*C12 | J12: =G12*H12 | O12: =L12*M12 | T12: =Q12*R12 | Y12: =V12*W12 | AA12: =IFERROR(((I12-D12)/D12)*100,"") | AB12: =IFERROR(((N12-D12)/D12)*100,"") | AC12: =IFERROR(((S12-D12)/D12)*100,"") | AD12: =IFERROR(((X12-D12)/D12)*100,"")
A13: Gêmeos Máquina em Pé | E13: =B13*C13 | J13: =G13*H13 | O13: =L13*M13 | T13: =Q13*R13 | Y13: =V13*W13 | AA13: =IFERROR(((I13-D13)/D13)*100,"") | AB13: =IFERROR(((N13-D13)/D13)*100,"") | AC13: =IFERROR(((S13-D13)/D13)*100,"") | AD13: =IFERROR(((X13-D13)/D13)*100,"")
E14: =B14*C14 | J14: =G14*H14 | O14: =L14*M14 | T14: =Q14*R14 | Y14: =V14*W14 | AA14: =IFERROR(((I14-D14)/D14)*100,"") | AB14: =IFERROR(((N14-D14)/D14)*100,"") | AC14: =IFERROR(((S14-D14)/D14)*100,"") | AD14: =IFERROR(((X14-D14)/D14)*100,"")
E15: =B15*C15 | J15: =G15*H15 | O15: =L15*M15 | T15: =Q15*R15 | Y15: =V15*W15 | AA15: =IFERROR(((I15-D15)/D15)*100,"") | AB15: =IFERROR(((N15-D15)/D15)*100,"") | AC15: =IFERROR(((S15-D15)/D15)*100,"") | AD15: =IFERROR(((X15-D15)/D15)*100,"")
E16: =B16*C16 | J16: =G16*H16 | O16: =L16*M16 | T16: =Q16*R16 | Y16: =V16*W16 | AA16: =IFERROR(((I16-D16)/D16)*100,"") | AB16: =IFERROR(((N16-D16)/D16)*100,"") | AC16: =IFERROR(((S16-D16)/D16)*100,"") | AD16: =IFERROR(((X16-D16)/D16)*100,"") | AN16: =AH16*AH15 | AO16: =AJ16*AJ15 | AP16: =AK16*AK15 | AQ16: =AL16*AL15
E17: PR | J17: PR | O17: PR | T17: PR | AC17: PR-M | AD17: =IFERROR(AVERAGE(G17,L17,Q17,V17),"")
E18: =SUM(E5:E16) | J18: =SUM(J5:J16) | O18: =SUM(O5:O16) | T18: =SUM(T5:T16) | Y18: =SUM(Y5:Y16)
L19: Son | M19: Estr | N19: Fad | O19: Dor | Q19: Média | T19: Teste de potência
A20: TERÇA-FEIRA | C20: DATA | Q20: =IFERROR(AVERAGE(L20:O20),"") | S20: =Q20
A21: Exercícios | B21: série 1 | G21: série 2 | L21: série 3 | Q21: série 4 | V21: série 5 | AA21: VEL (2x1) | AB21: VEL (3x1) | AC21: VEL (4x1) | AD21: VEL (5x1) | AG21: VTT-SESSÃO | AJ21: CARGA DE TREINO (U.A)
B22: nº reps | C22: peso(kg) | D22: veloc(s) | E22: VTT (sér) | G22: nº reps | H22: peso(kg) | I22: veloc(s) | J22: VTT (sér) | L22: nº reps | M22: peso(kg) | N22: veloc(s) | O22: VTT (sér) | Q22: nº reps | R22: peso(kg) | S22: veloc(s) | T22: VTT (sér) | V22: nº reps | W22: peso(kg) | X22: veloc(s) | Y22: VTT (sér) | AG22: =SUM(E36+J36+O36+T36+Y36) | AJ22: =AE23*AG25
E23: =B23*C23 | J23: =G23*H23 | O23: =L23*M23 | T23: =Q23*R23 | Y23: =V23*W23 | AA23: =IFERROR(((I23-D23)/D23)*100,"") | AB23: =IFERROR(((N23-D23)/D23)*100,"") | AC23: =IFERROR(((S23-D23)/D23)*100,"") | AD23: =IFERROR(((X23-D23)/D23)*100,"")
A24: Supino Inclinado Smith 30° | E24: =B24*C24 | J24: =G24*H24 | O24: =L24*M24 | T24: =Q24*R24 | Y24: =V24*W24 | AA24: =IFERROR(((I24-D24)/D24)*100,"") | AB24: =IFERROR(((N24-D24)/D24)*100,"") | AC24: =IFERROR(((S24-D24)/D24)*100,"") | AD24: =IFERROR(((X24-D24)/D24)*100,"") | AG24: Tempo total sessão (min)
A25: Fly Inclinado Banco 30° | E25: =B25*C25 | J25: =G25*H25 | O25: =L25*M25 | T25: =Q25*R25 | Y25: =V25*W25 | AA25: =IFERROR(((I25-D25)/D25)*100,"") | AB25: =IFERROR(((N25-D25)/D25)*100,"") | AC25: =IFERROR(((S25-D25)/D25)*100,"") | AD25: =IFERROR(((X25-D25)/D25)*100,"")
A26: Fly Reto | E26: =B26*C26 | J26: =G26*H26 | O26: =L26*M26 | T26: =Q26*R26 | Y26: =V26*W26 | AA26: =IFERROR(((I26-D26)/D26)*100,"") | AB26: =IFERROR(((N26-D26)/D26)*100,"") | AC26: =IFERROR(((S26-D26)/D26)*100,"") | AD26: =IFERROR(((X26-D26)/D26)*100,"")
A27: Cross-over | E27: =B27*C27 | J27: =G27*H27 | O27: =L27*M27 | T27: =Q27*R27 | Y27: =V27*W27 | AA27: =IFERROR(((I27-D27)/D27)*100,"") | AB27: =IFERROR(((N27-D27)/D27)*100,"") | AC27: =IFERROR(((S27-D27)/D27)*100,"") | AD27: =IFERROR(((X27-D27)/D27)*100,"")
A28: Crucifixo em Máquina | E28: =B28*C28 | J28: =G28*H28 | O28: =L28*M28 | T28: =Q28*R28 | Y28: =V28*W28 | AA28: =IFERROR(((I28-D28)/D28)*100,"") | AB28: =IFERROR(((N28-D28)/D28)*100,"") | AC28: =IFERROR(((S28-D28)/D28)*100,"") | AD28: =IFERROR(((X28-D28)/D28)*100,"")
A29: Elevação Frontal Corda | E29: =B29*C29 | J29: =G29*H29 | O29: =L29*M29 | T29: =Q29*R29 | Y29: =V29*W29 | AA29: =IFERROR(((I29-D29)/D29)*100,"") | AB29: =IFERROR(((N29-D29)/D29)*100,"") | AC29: =IFERROR(((S29-D29)/D29)*100,"") | AD29: =IFERROR(((X29-D29)/D29)*100,"")
A30: Flexão Quadril/Coluna Paralelas | E30: =B30*C30 | J30: =G30*H30 | O30: =L30*M30 | T30: =Q30*R30 | Y30: =V30*W30 | AA30: =IFERROR(((I30-D30)/D30)*100,"") | AB30: =IFERROR(((N30-D30)/D30)*100,"") | AC30: =IFERROR(((S30-D30)/D30)*100,"") | AD30: =IFERROR(((X30-D30)/D30)*100,"")
A31: Flexão de Coluna Máquina | E31: =B31*C31 | J31: =G31*H31 | O31: =L31*M31 | T31: =Q31*R31 | Y31: =V31*W31 | AA31: =IFERROR(((I31-D31)/D31)*100,"") | AB31: =IFERROR(((N31-D31)/D31)*100,"") | AC31: =IFERROR(((S31-D31)/D31)*100,"") | AD31: =IFERROR(((X31-D31)/D31)*100,"")
E32: =B32*C32 | J32: =G32*H32 | O32: =L32*M32 | T32: =Q32*R32 | Y32: =V32*W32 | AA32: =IFERROR(((I32-D32)/D32)*100,"") | AB32: =IFERROR(((N32-D32)/D32)*100,"") | AC32: =IFERROR(((S32-D32)/D32)*100,"") | AD32: =IFERROR(((X32-D32)/D32)*100,"")
E33: =B33*C33 | J33: =G33*H33 | O33: =L33*M33 | T33: =Q33*R33 | Y33: =V33*W33 | AA33: =IFERROR(((I33-D33)/D33)*100,"") | AB33: =IFERROR(((N33-D33)/D33)*100,"") | AC33: =IFERROR(((S33-D33)/D33)*100,"") | AD33: =IFERROR(((X33-D33)/D33)*100,"")
E34: =B34*C34 | J34: =G34*H34 | O34: =L34*M34 | T34: =Q34*R34 | Y34: =V34*W34 | AA34: =IFERROR(((I34-D34)/D34)*100,"") | AB34: =IFERROR(((N34-D34)/D34)*100,"") | AC34: =IFERROR(((S34-D34)/D34)*100,"") | AD34: =IFERROR(((X34-D34)/D34)*100,"") | AM34: =AG34*AG33 | AN34: =AH34*AH33 | AO34: =AJ34*AJ33 | AP34: =AK34*AK33 | AQ34: =AL34*AL33
E35: PR | J35: PR | O35: PR | T35: PR | AC35: PR-M | AD35: =IFERROR(AVERAGE(G35,L35,Q35,V35),"")
E36: =SUM(E23:E34) | J36: =SUM(J23:J34) | O36: =SUM(O23:O34) | T36: =SUM(T23:T34) | Y36: =SUM(Y23:Y34)
L37: Son | M37: Estr | N37: Fad | O37: Dor | Q37: Média | T37: Teste de potência
A38: QUARTA-FEIRA | C38: DATA | Q38: =IFERROR(AVERAGE(L38:O38),"") | S38: =Q38
A39: Exercícios | B39: série 1 | G39: série 2 | L39: série 3 | Q39: série 4 | V39: série 5 | AA39: VEL (2x1) | AB39: VEL (3x1) | AC39: VEL (4x1) | AD39: VEL (5x1) | AG39: VTT-SESSÃO | AJ39: CARGA DE TREINO (U.A)
B40: nº reps | C40: peso(kg) | D40: veloc(s) | E40: VTT (sér) | G40: nº reps | H40: peso(kg) | I40: veloc(s) | J40: VTT (sér) | L40: nº reps | M40: peso(kg) | N40: veloc(s) | O40: VTT (sér) | Q40: nº reps | R40: peso(kg) | S40: veloc(s) | T40: VTT (sér) | V40: nº reps | W40: peso(kg) | X40: veloc(s) | Y40: VTT (sér) | AG40: =SUM(E54+J54+O54+T54+Y54) | AJ40: =AE41*AG43
...

Sheet SEM 6
A1: SEMANA 6 | L1: Son | M1: Estr | N1: Fad | O1: Dor | Q1: Média | T1: Teste de potência
A2: SEGUNDA-FEIRA | C2: DATA | Q2: =IFERROR(AVERAGE(L2:O2),"") | S2: =Q2
A3: Exercícios | B3: série 1 | G3: série 2 | L3: série 3 | Q3: série 4 | V3: série 5 | AA3: VEL (2x1) | AB3: VEL (3x1) | AC3: VEL (4x1) | AD3: VEL (5x1) | AG3: VTT-SESSÃO | AJ3: CARGA DE TREINO (U.A)
B4: nº reps | C4: peso(kg) | D4: veloc(s) | E4: VTT (sér) | G4: nº reps | H4: peso(kg) | I4: veloc(s) | J4: VTT (sér) | L4: nº reps | M4: peso(kg) | N4: veloc(s) | O4: VTT (sér) | Q4: nº reps | R4: peso(kg) | S4: veloc(s) | T4: VTT (sér) | V4: nº reps | W4: peso(kg) | X4: veloc(s) | Y4: VTT (sér) | AG4: =SUM(E18+J18+O18+T18+Y18) | AJ4: =AE5*AG7
E5: =B5*C5 | J5: =G5*H5 | O5: =L5*M5 | T5: =Q5*R5 | Y5: =V5*W5 | AA5: =IFERROR(((I5-D5)/D5)*100,"") | AB5: =IFERROR(((N5-D5)/D5)*100,"") | AC5: =IFERROR(((S5-D5)/D5)*100,"") | AD5: =IFERROR(((X5-D5)/D5)*100,"")
A6: Cadeira Abdutora 90° | E6: =B6*C6 | J6: =G6*H6 | O6: =L6*M6 | T6: =Q6*R6 | Y6: =V6*W6 | AA6: =IFERROR(((I6-D6)/D6)*100,"") | AB6: =IFERROR(((N6-D6)/D6)*100,"") | AC6: =IFERROR(((S6-D6)/D6)*100,"") | AD6: =IFERROR(((X6-D6)/D6)*100,"") | AG6: Tempo total sessão (min)
A7: Elevação Pélvica (livre/máq) | E7: =B7*C7 | J7: =G7*H7 | O7: =L7*M7 | T7: =Q7*R7 | Y7: =V7*W7 | AA7: =IFERROR(((I7-D7)/D7)*100,"") | AB7: =IFERROR(((N7-D7)/D7)*100,"") | AC7: =IFERROR(((S7-D7)/D7)*100,"") | AD7: =IFERROR(((X7-D7)/D7)*100,"")
A8: Afundo no Smith | E8: =B8*C8 | J8: =G8*H8 | O8: =L8*M8 | T8: =Q8*R8 | Y8: =V8*W8 | AA8: =IFERROR(((I8-D8)/D8)*100,"") | AB8: =IFERROR(((N8-D8)/D8)*100,"") | AC8: =IFERROR(((S8-D8)/D8)*100,"") | AD8: =IFERROR(((X8-D8)/D8)*100,"")
A9: Agachamento Livre | E9: =B9*C9 | J9: =G9*H9 | O9: =L9*M9 | T9: =Q9*R9 | Y9: =V9*W9 | AA9: =IFERROR(((I9-D9)/D9)*100,"") | AB9: =IFERROR(((N9-D9)/D9)*100,"") | AC9: =IFERROR(((S9-D9)/D9)*100,"") | AD9: =IFERROR(((X9-D9)/D9)*100,"")
A10: Leg Press 45° | E10: =B10*C10 | J10: =G10*H10 | O10: =L10*M10 | T10: =Q10*R10 | Y10: =V10*W10 | AA10: =IFERROR(((I10-D10)/D10)*100,"") | AB10: =IFERROR(((N10-D10)/D10)*100,"") | AC10: =IFERROR(((S10-D10)/D10)*100,"") | AD10: =IFERROR(((X10-D10)/D10)*100,"")
A11: Cadeira Extensora | E11: =B11*C11 | J11: =G11*H11 | O11: =L11*M11 | T11: =Q11*R11 | Y11: =V11*W11 | AA11: =IFERROR(((I11-D11)/D11)*100,"") | AB11: =IFERROR(((N11-D11)/D11)*100,"") | AC11: =IFERROR(((S11-D11)/D11)*100,"") | AD11: =IFERROR(((X11-D11)/D11)*100,"")
A12: Gêmeos Sentado | E12: =B12*C12 | J12: =G12*H12 | O12: =L12*M12 | T12: =Q12*R12 | Y12: =V12*W12 | AA12: =IFERROR(((I12-D12)/D12)*100,"") | AB12: =IFERROR(((N12-D12)/D12)*100,"") | AC12: =IFERROR(((S12-D12)/D12)*100,"") | AD12: =IFERROR(((X12-D12)/D12)*100,"")
A13: Gêmeos Máquina em Pé | E13: =B13*C13 | J13: =G13*H13 | O13: =L13*M13 | T13: =Q13*R13 | Y13: =V13*W13 | AA13: =IFERROR(((I13-D13)/D13)*100,"") | AB13: =IFERROR(((N13-D13)/D13)*100,"") | AC13: =IFERROR(((S13-D13)/D13)*100,"") | AD13: =IFERROR(((X13-D13)/D13)*100,"")
E14: =B14*C14 | J14: =G14*H14 | O14: =L14*M14 | T14: =Q14*R14 | Y14: =V14*W14 | AA14: =IFERROR(((I14-D14)/D14)*100,"") | AB14: =IFERROR(((N14-D14)/D14)*100,"") | AC14: =IFERROR(((S14-D14)/D14)*100,"") | AD14: =IFERROR(((X14-D14)/D14)*100,"")
E15: =B15*C15 | J15: =G15*H15 | O15: =L15*M15 | T15: =Q15*R15 | Y15: =V15*W15 | AA15: =IFERROR(((I15-D15)/D15)*100,"") | AB15: =IFERROR(((N15-D15)/D15)*100,"") | AC15: =IFERROR(((S15-D15)/D15)*100,"") | AD15: =IFERROR(((X15-D15)/D15)*100,"")
E16: =B16*C16 | J16: =G16*H16 | O16: =L16*M16 | T16: =Q16*R16 | Y16: =V16*W16 | AA16: =IFERROR(((I16-D16)/D16)*100,"") | AB16: =IFERROR(((N16-D16)/D16)*100,"") | AC16: =IFERROR(((S16-D16)/D16)*100,"") | AD16: =IFERROR(((X16-D16)/D16)*100,"") | AN16: =AH16*AH15 | AO16: =AJ16*AJ15 | AP16: =AK16*AK15 | AQ16: =AL16*AL15
E17: PR | J17: PR | O17: PR | T17: PR | AC17: PR-M | AD17: =IFERROR(AVERAGE(G17,L17,Q17,V17),"")
E18: =SUM(E5:E16) | J18: =SUM(J5:J16) | O18: =SUM(O5:O16) | T18: =SUM(T5:T16) | Y18: =SUM(Y5:Y16)
L19: Son | M19: Estr | N19: Fad | O19: Dor | Q19: Média | T19: Teste de potência
A20: TERÇA-FEIRA | C20: DATA | Q20: =IFERROR(AVERAGE(L20:O20),"") | S20: =Q20
A21: Exercícios | B21: série 1 | G21: série 2 | L21: série 3 | Q21: série 4 | V21: série 5 | AA21: VEL (2x1) | AB21: VEL (3x1) | AC21: VEL (4x1) | AD21: VEL (5x1) | AG21: VTT-SESSÃO | AJ21: CARGA DE TREINO (U.A)
B22: nº reps | C22: peso(kg) | D22: veloc(s) | E22: VTT (sér) | G22: nº reps | H22: peso(kg) | I22: veloc(s) | J22: VTT (sér) | L22: nº reps | M22: peso(kg) | N22: veloc(s) | O22: VTT (sér) | Q22: nº reps | R22: peso(kg) | S22: veloc(s) | T22: VTT (sér) | V22: nº reps | W22: peso(kg) | X22: veloc(s) | Y22: VTT (sér) | AG22: =SUM(E36+J36+O36+T36+Y36) | AJ22: =AE23*AG25
E23: =B23*C23 | J23: =G23*H23 | O23: =L23*M23 | T23: =Q23*R23 | Y23: =V23*W23 | AA23: =IFERROR(((I23-D23)/D23)*100,"") | AB23: =IFERROR(((N23-D23)/D23)*100,"") | AC23: =IFERROR(((S23-D23)/D23)*100,"") | AD23: =IFERROR(((X23-D23)/D23)*100,"")
A24: Supino Inclinado Smith 30° | E24: =B24*C24 | J24: =G24*H24 | O24: =L24*M24 | T24: =Q24*R24 | Y24: =V24*W24 | AA24: =IFERROR(((I24-D24)/D24)*100,"") | AB24: =IFERROR(((N24-D24)/D24)*100,"") | AC24: =IFERROR(((S24-D24)/D24)*100,"") | AD24: =IFERROR(((X24-D24)/D24)*100,"") | AG24: Tempo total sessão (min)
A25: Fly Inclinado Banco 30° | E25: =B25*C25 | J25: =G25*H25 | O25: =L25*M25 | T25: =Q25*R25 | Y25: =V25*W25 | AA25: =IFERROR(((I25-D25)/D25)*100,"") | AB25: =IFERROR(((N25-D25)/D25)*100,"") | AC25: =IFERROR(((S25-D25)/D25)*100,"") | AD25: =IFERROR(((X25-D25)/D25)*100,"")
A26: Fly Reto | E26: =B26*C26 | J26: =G26*H26 | O26: =L26*M26 | T26: =Q26*R26 | Y26: =V26*W26 | AA26: =IFERROR(((I26-D26)/D26)*100,"") | AB26: =IFERROR(((N26-D26)/D26)*100,"") | AC26: =IFERROR(((S26-D26)/D26)*100,"") | AD26: =IFERROR(((X26-D26)/D26)*100,"")
A27: Cross-over | E27: =B27*C27 | J27: =G27*H27 | O27: =L27*M27 | T27: =Q27*R27 | Y27: =V27*W27 | AA27: =IFERROR(((I27-D27)/D27)*100,"") | AB27: =IFERROR(((N27-D27)/D27)*100,"") | AC27: =IFERROR(((S27-D27)/D27)*100,"") | AD27: =IFERROR(((X27-D27)/D27)*100,"")
A28: Crucifixo em Máquina | E28: =B28*C28 | J28: =G28*H28 | O28: =L28*M28 | T28: =Q28*R28 | Y28: =V28*W28 | AA28: =IFERROR(((I28-D28)/D28)*100,"") | AB28: =IFERROR(((N28-D28)/D28)*100,"") | AC28: =IFERROR(((S28-D28)/D28)*100,"") | AD28: =IFERROR(((X28-D28)/D28)*100,"")
A29: Elevação Frontal Corda | E29: =B29*C29 | J29: =G29*H29 | O29: =L29*M29 | T29: =Q29*R29 | Y29: =V29*W29 | AA29: =IFERROR(((I29-D29)/D29)*100,"") | AB29: =IFERROR(((N29-D29)/D29)*100,"") | AC29: =IFERROR(((S29-D29)/D29)*100,"") | AD29: =IFERROR(((X29-D29)/D29)*100,"")
A30: Flexão Quadril/Coluna Paralelas | E30: =B30*C30 | J30: =G30*H30 | O30: =L30*M30 | T30: =Q30*R30 | Y30: =V30*W30 | AA30: =IFERROR(((I30-D30)/D30)*100,"") | AB30: =IFERROR(((N30-D30)/D30)*100,"") | AC30: =IFERROR(((S30-D30)/D30)*100,"") | AD30: =IFERROR(((X30-D30)/D30)*100,"")
A31: Flexão de Coluna Máquina | E31: =B31*C31 | J31: =G31*H31 | O31: =L31*M31 | T31: =Q31*R31 | Y31: =V31*W31 | AA31: =IFERROR(((I31-D31)/D31)*100,"") | AB31: =IFERROR(((N31-D31)/D31)*100,"") | AC31: =IFERROR(((S31-D31)/D31)*100,"") | AD31: =IFERROR(((X31-D31)/D31)*100,"")
E32: =B32*C32 | J32: =G32*H32 | O32: =L32*M32 | T32: =Q32*R32 | Y32: =V32*W32 | AA32: =IFERROR(((I32-D32)/D32)*100,"") | AB32: =IFERROR(((N32-D32)/D32)*100,"") | AC32: =IFERROR(((S32-D32)/D32)*100,"") | AD32: =IFERROR(((X32-D32)/D32)*100,"")
E33: =B33*C33 | J33: =G33*H33 | O33: =L33*M33 | T33: =Q33*R33 | Y33: =V33*W33 | AA33: =IFERROR(((I33-D33)/D33)*100,"") | AB33: =IFERROR(((N33-D33)/D33)*100,"") | AC33: =IFERROR(((S33-D33)/D33)*100,"") | AD33: =IFERROR(((X33-D33)/D33)*100,"")
E34: =B34*C34 | J34: =G34*H34 | O34: =L34*M34 | T34: =Q34*R34 | Y34: =V34*W34 | AA34: =IFERROR(((I34-D34)/D34)*100,"") | AB34: =IFERROR(((N34-D34)/D34)*100,"") | AC34: =IFERROR(((S34-D34)/D34)*100,"") | AD34: =IFERROR(((X34-D34)/D34)*100,"") | AM34: =AG34*AG33 | AN34: =AH34*AH33 | AO34: =AJ34*AJ33 | AP34: =AK34*AK33 | AQ34: =AL34*AL33
E35: PR | J35: PR | O35: PR | T35: PR | AC35: PR-M | AD35: =IFERROR(AVERAGE(G35,L35,Q35,V35),"")
E36: =SUM(E23:E34) | J36: =SUM(J23:J34) | O36: =SUM(O23:O34) | T36: =SUM(T23:T34) | Y36: =SUM(Y23:Y34)
L37: Son | M37: Estr | N37: Fad | O37: Dor | Q37: Média | T37: Teste de potência
A38: QUARTA-FEIRA | C38: DATA | Q38: =IFERROR(AVERAGE(L38:O38),"") | S38: =Q38
A39: Exercícios | B39: série 1 | G39: série 2 | L39: série 3 | Q39: série 4 | V39: série 5 | AA39: VEL (2x1) | AB39: VEL (3x1) | AC39: VEL (4x1) | AD39: VEL (5x1) | AG39: VTT-SESSÃO | AJ39: CARGA DE TREINO (U.A)
B40: nº reps | C40: peso(kg) | D40: veloc(s) | E40: VTT (sér) | G40: nº reps | H40: peso(kg) | I40: veloc(s) | J40: VTT (sér) | L40: nº reps | M40: peso(kg) | N40: veloc(s) | O40: VTT (sér) | Q40: nº reps | R40: peso(kg) | S40: veloc(s) | T40: VTT (sér) | V40: nº reps | W40: peso(kg) | X40: veloc(s) | Y40: VTT (sér) | AG40: =SUM(E54+J54+O54+T54+Y54) | AJ40: =AE41*AG43
...

Sheet SEM 7
A1: SEMANA 7 | L1: Son | M1: Estr | N1: Fad | O1: Dor | Q1: Média | T1: Teste de potência
A2: SEGUNDA-FEIRA | C2: DATA | Q2: =IFERROR(AVERAGE(L2:O2),"") | S2: =Q2
A3: Exercícios | B3: série 1 | G3: série 2 | L3: série 3 | Q3: série 4 | V3: série 5 | AA3: VEL (2x1) | AB3: VEL (3x1) | AC3: VEL (4x1) | AD3: VEL (5x1) | AG3: VTT-SESSÃO | AJ3: CARGA DE TREINO (U.A)
B4: nº reps | C4: peso(kg) | D4: veloc(s) | E4: VTT (sér) | G4: nº reps | H4: peso(kg) | I4: veloc(s) | J4: VTT (sér) | L4: nº reps | M4: peso(kg) | N4: veloc(s) | O4: VTT (sér) | Q4: nº reps | R4: peso(kg) | S4: veloc(s) | T4: VTT (sér) | V4: nº reps | W4: peso(kg) | X4: veloc(s) | Y4: VTT (sér) | AG4: =SUM(E18+J18+O18+T18+Y18) | AJ4: =AE5*AG7
E5: =B5*C5 | J5: =G5*H5 | O5: =L5*M5 | T5: =Q5*R5 | Y5: =V5*W5 | AA5: =IFERROR(((I5-D5)/D5)*100,"") | AB5: =IFERROR(((N5-D5)/D5)*100,"") | AC5: =IFERROR(((S5-D5)/D5)*100,"") | AD5: =IFERROR(((X5-D5)/D5)*100,"")
A6: Cadeira Abdutora 90° | E6: =B6*C6 | J6: =G6*H6 | O6: =L6*M6 | T6: =Q6*R6 | Y6: =V6*W6 | AA6: =IFERROR(((I6-D6)/D6)*100,"") | AB6: =IFERROR(((N6-D6)/D6)*100,"") | AC6: =IFERROR(((S6-D6)/D6)*100,"") | AD6: =IFERROR(((X6-D6)/D6)*100,"") | AG6: Tempo total sessão (min)
A7: Elevação Pélvica (livre/máq) | E7: =B7*C7 | J7: =G7*H7 | O7: =L7*M7 | T7: =Q7*R7 | Y7: =V7*W7 | AA7: =IFERROR(((I7-D7)/D7)*100,"") | AB7: =IFERROR(((N7-D7)/D7)*100,"") | AC7: =IFERROR(((S7-D7)/D7)*100,"") | AD7: =IFERROR(((X7-D7)/D7)*100,"")
A8: Afundo no Smith | E8: =B8*C8 | J8: =G8*H8 | O8: =L8*M8 | T8: =Q8*R8 | Y8: =V8*W8 | AA8: =IFERROR(((I8-D8)/D8)*100,"") | AB8: =IFERROR(((N8-D8)/D8)*100,"") | AC8: =IFERROR(((S8-D8)/D8)*100,"") | AD8: =IFERROR(((X8-D8)/D8)*100,"")
A9: Agachamento Livre | E9: =B9*C9 | J9: =G9*H9 | O9: =L9*M9 | T9: =Q9*R9 | Y9: =V9*W9 | AA9: =IFERROR(((I9-D9)/D9)*100,"") | AB9: =IFERROR(((N9-D9)/D9)*100,"") | AC9: =IFERROR(((S9-D9)/D9)*100,"") | AD9: =IFERROR(((X9-D9)/D9)*100,"")
A10: Leg Press 45° | E10: =B10*C10 | J10: =G10*H10 | O10: =L10*M10 | T10: =Q10*R10 | Y10: =V10*W10 | AA10: =IFERROR(((I10-D10)/D10)*100,"") | AB10: =IFERROR(((N10-D10)/D10)*100,"") | AC10: =IFERROR(((S10-D10)/D10)*100,"") | AD10: =IFERROR(((X10-D10)/D10)*100,"")
A11: Cadeira Extensora | E11: =B11*C11 | J11: =G11*H11 | O11: =L11*M11 | T11: =Q11*R11 | Y11: =V11*W11 | AA11: =IFERROR(((I11-D11)/D11)*100,"") | AB11: =IFERROR(((N11-D11)/D11)*100,"") | AC11: =IFERROR(((S11-D11)/D11)*100,"") | AD11: =IFERROR(((X11-D11)/D11)*100,"")
A12: Gêmeos Sentado | E12: =B12*C12 | J12: =G12*H12 | O12: =L12*M12 | T12: =Q12*R12 | Y12: =V12*W12 | AA12: =IFERROR(((I12-D12)/D12)*100,"") | AB12: =IFERROR(((N12-D12)/D12)*100,"") | AC12: =IFERROR(((S12-D12)/D12)*100,"") | AD12: =IFERROR(((X12-D12)/D12)*100,"")
A13: Gêmeos Máquina em Pé | E13: =B13*C13 | J13: =G13*H13 | O13: =L13*M13 | T13: =Q13*R13 | Y13: =V13*W13 | AA13: =IFERROR(((I13-D13)/D13)*100,"") | AB13: =IFERROR(((N13-D13)/D13)*100,"") | AC13: =IFERROR(((S13-D13)/D13)*100,"") | AD13: =IFERROR(((X13-D13)/D13)*100,"")
E14: =B14*C14 | J14: =G14*H14 | O14: =L14*M14 | T14: =Q14*R14 | Y14: =V14*W14 | AA14: =IFERROR(((I14-D14)/D14)*100,"") | AB14: =IFERROR(((N14-D14)/D14)*100,"") | AC14: =IFERROR(((S14-D14)/D14)*100,"") | AD14: =IFERROR(((X14-D14)/D14)*100,"")
E15: =B15*C15 | J15: =G15*H15 | O15: =L15*M15 | T15: =Q15*R15 | Y15: =V15*W15 | AA15: =IFERROR(((I15-D15)/D15)*100,"") | AB15: =IFERROR(((N15-D15)/D15)*100,"") | AC15: =IFERROR(((S15-D15)/D15)*100,"") | AD15: =IFERROR(((X15-D15)/D15)*100,"")
E16: =B16*C16 | J16: =G16*H16 | O16: =L16*M16 | T16: =Q16*R16 | Y16: =V16*W16 | AA16: =IFERROR(((I16-D16)/D16)*100,"") | AB16: =IFERROR(((N16-D16)/D16)*100,"") | AC16: =IFERROR(((S16-D16)/D16)*100,"") | AD16: =IFERROR(((X16-D16)/D16)*100,"") | AN16: =AH16*AH15 | AO16: =AJ16*AJ15 | AP16: =AK16*AK15 | AQ16: =AL16*AL15
E17: PR | J17: PR | O17: PR | T17: PR | AC17: PR-M | AD17: =IFERROR(AVERAGE(G17,L17,Q17,V17),"")
E18: =SUM(E5:E16) | J18: =SUM(J5:J16) | O18: =SUM(O5:O16) | T18: =SUM(T5:T16) | Y18: =SUM(Y5:Y16)
L19: Son | M19: Estr | N19: Fad | O19: Dor | Q19: Média | T19: Teste de potência
A20: TERÇA-FEIRA | C20: DATA | Q20: =IFERROR(AVERAGE(L20:O20),"") | S20: =Q20
A21: Exercícios | B21: série 1 | G21: série 2 | L21: série 3 | Q21: série 4 | V21: série 5 | AA21: VEL (2x1) | AB21: VEL (3x1) | AC21: VEL (4x1) | AD21: VEL (5x1) | AG21: VTT-SESSÃO | AJ21: CARGA DE TREINO (U.A)
B22: nº reps | C22: peso(kg) | D22: veloc(s) | E22: VTT (sér) | G22: nº reps | H22: peso(kg) | I22: veloc(s) | J22: VTT (sér) | L22: nº reps | M22: peso(kg) | N22: veloc(s) | O22: VTT (sér) | Q22: nº reps | R22: peso(kg) | S22: veloc(s) | T22: VTT (sér) | V22: nº reps | W22: peso(kg) | X22: veloc(s) | Y22: VTT (sér) | AG22: =SUM(E36+J36+O36+T36+Y36) | AJ22: =AE23*AG25
E23: =B23*C23 | J23: =G23*H23 | O23: =L23*M23 | T23: =Q23*R23 | Y23: =V23*W23 | AA23: =IFERROR(((I23-D23)/D23)*100,"") | AB23: =IFERROR(((N23-D23)/D23)*100,"") | AC23: =IFERROR(((S23-D23)/D23)*100,"") | AD23: =IFERROR(((X23-D23)/D23)*100,"")
A24: Supino Inclinado Smith 30° | E24: =B24*C24 | J24: =G24*H24 | O24: =L24*M24 | T24: =Q24*R24 | Y24: =V24*W24 | AA24: =IFERROR(((I24-D24)/D24)*100,"") | AB24: =IFERROR(((N24-D24)/D24)*100,"") | AC24: =IFERROR(((S24-D24)/D24)*100,"") | AD24: =IFERROR(((X24-D24)/D24)*100,"") | AG24: Tempo total sessão (min)
A25: Fly Inclinado Banco 30° | E25: =B25*C25 | J25: =G25*H25 | O25: =L25*M25 | T25: =Q25*R25 | Y25: =V25*W25 | AA25: =IFERROR(((I25-D25)/D25)*100,"") | AB25: =IFERROR(((N25-D25)/D25)*100,"") | AC25: =IFERROR(((S25-D25)/D25)*100,"") | AD25: =IFERROR(((X25-D25)/D25)*100,"")
A26: Fly Reto | E26: =B26*C26 | J26: =G26*H26 | O26: =L26*M26 | T26: =Q26*R26 | Y26: =V26*W26 | AA26: =IFERROR(((I26-D26)/D26)*100,"") | AB26: =IFERROR(((N26-D26)/D26)*100,"") | AC26: =IFERROR(((S26-D26)/D26)*100,"") | AD26: =IFERROR(((X26-D26)/D26)*100,"")
A27: Cross-over | E27: =B27*C27 | J27: =G27*H27 | O27: =L27*M27 | T27: =Q27*R27 | Y27: =V27*W27 | AA27: =IFERROR(((I27-D27)/D27)*100,"") | AB27: =IFERROR(((N27-D27)/D27)*100,"") | AC27: =IFERROR(((S27-D27)/D27)*100,"") | AD27: =IFERROR(((X27-D27)/D27)*100,"")
A28: Crucifixo em Máquina | E28: =B28*C28 | J28: =G28*H28 | O28: =L28*M28 | T28: =Q28*R28 | Y28: =V28*W28 | AA28: =IFERROR(((I28-D28)/D28)*100,"") | AB28: =IFERROR(((N28-D28)/D28)*100,"") | AC28: =IFERROR(((S28-D28)/D28)*100,"") | AD28: =IFERROR(((X28-D28)/D28)*100,"")
